Workbook
Name Afirmativa: OFFSET('[1]Listas (Hide)'!$B$13,1,MATCH('[1]General Information'!$F$4,'[1]Listas (Hide)'!$B$13:$D$13,0)-1,2)
Name Afirmativa: OFFSET('[2]Listas (Hide)'!$B$13,1,MATCH('[2]General Information'!$F$4,'[2]Listas (Hide)'!$B$13:$D$13,0)-1,2)
Name Afirmativa: OFFSET('Listas (Hide)'!$B$16,1,MATCH(Proposal!#REF!,'Listas (Hide)'!$B$16:$D$16,0)-1,2)
Name Afirmativa: OFFSET('Listas (Hide)'!$B$16,1,MATCH('General Information'!$C$6,'Listas (Hide)'!$B$16:$D$16,0)-1,2)
Name Assistencial: OFFSET('[1]Listas (Hide)'!$B$72,1,MATCH('[1]General Information'!$F$4,'[1]Listas (Hide)'!$B$72:$D$72,0)-1,3)
Name Assistencial: OFFSET('[2]Listas (Hide)'!$B$72,1,MATCH('[2]General Information'!$F$4,'[2]Listas (Hide)'!$B$72:$D$72,0)-1,3)
Name Assistencial: OFFSET('Listas (Hide)'!$B$75,1,MATCH('General Information'!$C$6,'Listas (Hide)'!$B$75:$D$75,0)-1,3)
Name Banco_sangue: OFFSET('[1]Listas (Hide)'!$B$17,1,MATCH('[1]General Information'!$F$4,'[1]Listas (Hide)'!$B$17:$D$17,0)-1,2)
Name Banco_sangue: OFFSET('[2]Listas (Hide)'!$B$17,1,MATCH('[2]General Information'!$F$4,'[2]Listas (Hide)'!$B$17:$D$17,0)-1,2)
Name Banco_sangue: OFFSET('Listas (Hide)'!$B$20,1,MATCH('General Information'!$C$6,'Listas (Hide)'!$B$20:$D$20,0)-1,2)
Name Cloud: OFFSET('[1]Listas (Hide)'!$B$116,1,MATCH('[1]General Information'!$F$4,'[1]Listas (Hide)'!$B$116:$D$116,0)-1,4)
Name Cloud: OFFSET('[2]Listas (Hide)'!$B$115,1,MATCH('[2]General Information'!$F$4,'[2]Listas (Hide)'!$B$115:$D$115,0)-1,4)
Name Cloud: OFFSET('Listas (Hide)'!$B$119,1,MATCH('General Information'!$C$6,'Listas (Hide)'!$B$119:$D$119,0)-1,4)
Name Deslocamento: OFFSET('[1]Listas (Hide)'!$B$80,1,MATCH('[1]General Information'!$F$4,'[1]Listas (Hide)'!$B$80:$D$80,0)-1,5)
Name Deslocamento: OFFSET('[2]Listas (Hide)'!$B$79,1,MATCH('[2]General Information'!$F$4,'[2]Listas (Hide)'!$B$79:$D$79,0)-1,5)
Name Deslocamento: OFFSET('Listas (Hide)'!$B$83,1,MATCH('General Information'!$C$6,'Listas (Hide)'!$B$83:$D$83,0)-1,5)
Name Mercados: OFFSET('[1]Listas (Hide)'!$B$98,1,MATCH('[1]General Information'!$F$4,'[1]Listas (Hide)'!$B$98:$D$98,0)-1,12)
Name Mercados: OFFSET('[2]Listas (Hide)'!$B$97,1,MATCH('[2]General Information'!$F$4,'[2]Listas (Hide)'!$B$97:$D$97,0)-1,12)
Name Mercados: OFFSET('Listas (Hide)'!$B$101,1,MATCH('General Information'!$C$6,'Listas (Hide)'!$B$101:$D$101,0)-1,12)
Name Onda_Implantacao: OFFSET('[1]Listas (Hide)'!$B$65,1,MATCH('[1]General Information'!$F$4,'[1]Listas (Hide)'!$B$65:$D$65,0)-1,2)
Name Onda_Implantacao: OFFSET('[2]Listas (Hide)'!$B$65,1,MATCH('[2]General Information'!$F$4,'[2]Listas (Hide)'!$B$65:$D$65,0)-1,2)
Name Onda_Implantacao: OFFSET('Listas (Hide)'!$B$68,1,MATCH('General Information'!$C$6,'Listas (Hide)'!$B$68:$D$68,0)-1,2)
Name Periodicidade: OFFSET('[1]Listas (Hide)'!$B$56,1,MATCH('[1]General Information'!$F$4,'[1]Listas (Hide)'!$B$56:$D$56,0)-1,4)
Name Periodicidade: OFFSET('[2]Listas (Hide)'!$B$56,1,MATCH('[2]General Information'!$F$4,'[2]Listas (Hide)'!$B$56:$D$56,0)-1,4)
Name Periodicidade: OFFSET('Listas (Hide)'!$B$59,1,MATCH('General Information'!$C$6,'Listas (Hide)'!$B$59:$D$59,0)-1,4)
Name Porte: OFFSET('[1]Listas (Hide)'!XFA1048568,1,MATCH('[1]General Information'!A1048568,'[1]Listas (Hide)'!XFA1048568:XFC1048568,0)-1,4)
Name Porte: OFFSET('[2]Listas (Hide)'!XFA1048568,1,MATCH('[2]General Information'!A1048568,'[2]Listas (Hide)'!XFA1048568:XFC1048568,0)-1,4)
Name Porte: OFFSET('Listas (Hide)'!XFA1048568,1,MATCH(Proposal!A1048568,'Listas (Hide)'!XFA1048568:XFC1048568,0)-1,4)
Name Porte: OFFSET('Listas (Hide)'!XFA1048568,1,MATCH('General Information'!A1048568,'Listas (Hide)'!XFA1048568:XFC1048568,0)-1,4)
Name Porte_Cliente: OFFSET('[1]Listas (Hide)'!$B$4,1,MATCH('[1]General Information'!$F$4,'[1]Listas (Hide)'!$B$4:$D$4,0)-1,6)
Name Porte_Cliente: OFFSET('[2]Listas (Hide)'!$B$4,1,MATCH('[2]General Information'!$F$4,'[2]Listas (Hide)'!$B$4:$D$4,0)-1,6)
Name Porte_Cliente: OFFSET('Listas (Hide)'!$B$4,1,MATCH('General Information'!$C$6,'Listas (Hide)'!$B$4:$D$4,0)-1,6)
Name Porte_v2: 'Listas (Hide)'!$A$5:$D$10
Name Porte_v3: 'Listas (Hide)'!$B$5:$B$10
Name Tipo_proposta: OFFSET('[1]Listas (Hide)'!$B$43,1,MATCH('[1]General Information'!$F$4,'[1]Listas (Hide)'!$B$43:$D$43,0)-1,3)
Name Tipo_proposta: OFFSET('[2]Listas (Hide)'!$B$43,1,MATCH('[2]General Information'!$F$4,'[2]Listas (Hide)'!$B$43:$D$43,0)-1,3)
Name Tipo_proposta: OFFSET('Listas (Hide)'!$B$46,1,MATCH('General Information'!$C$6,'Listas (Hide)'!$B$46:$D$46,0)-1,3)
Name Tipo_usuario: OFFSET('[1]Listas (Hide)'!$B$50,1,MATCH('[1]General Information'!$F$4,'[1]Listas (Hide)'!$B$50:$D$50,0)-1,2)
Name Tipo_usuario: OFFSET('[2]Listas (Hide)'!$B$50,1,MATCH('[2]General Information'!$F$4,'[2]Listas (Hide)'!$B$50:$D$50,0)-1,2)
Name Tipo_usuario: OFFSET('Listas (Hide)'!$B$53,1,MATCH('General Information'!$C$6,'Listas (Hide)'!$B$53:$D$53,0)-1,2)
Name TWS: OFFSET('[1]Listas (Hide)'!$B$89,1,MATCH('[1]General Information'!$F$4,'[1]Listas (Hide)'!$B$89:$D$89,0)-1,4)
Name TWS: OFFSET('[2]Listas (Hide)'!$B$88,1,MATCH('[2]General Information'!$F$4,'[2]Listas (Hide)'!$B$88:$D$88,0)-1,4)
Name TWS: OFFSET('Listas (Hide)'!$B$92,1,MATCH('General Information'!$C$6,'Listas (Hide)'!$B$92:$D$92,0)-1,4)

Sheet Version Control (Old-Delete)
A1: 2 | B1: =HLOOKUP('General Information'!$C$6,'IDIOMA (hide)'!$A$1:$D$5016,A1,0) -> LTEP - Levantamento Técnico de Estimativa de Projeto TASY EMR Código do documento: 0060 - Rev 024
B3: Version Control
B5: Version | C5: Date | D5: Date | E5: Description | F5: Responsible
B6: 12 | C6: 01/Apr/2019 | D6: 43535 | E6: Atualizada horas de implantação, alterada algumas perguntas, criado indicador de plataforma | F6: José Dallabrida
D7: 43538 | E7: Funções com horas 0 foram removidas de todos os escopos | F7: Diogo Benigo
D8: 43539 | E8: Excluido modulo ITEM PRONTUÁRIO, funções criadas PALM | F8: Diogo Benigo
D9: 43545 | E9: Criado planilha SP- Proposta | F9: Diogo Benigo
D10: 43546 | E10: Ajustes nos módulos, funções e perguntas | F10: Diogo Benigo
D11: 43550 | E11: Adicionada a aba de Integrações | F11: Anderson R. Tridapalli
D12: 43551 | E12: 1) Ajuste do Módulo Suporte a Decisão Clínica para ser incluído no caso de Hospital de Pequeno porte; 2) Inclusão de pergunta sobre Oftalmologia para inclusão de 40 horas no Prontuário Eletrônico Paciente; 3) Ajuste do número de horas do item do PEP Oftalmologia para 40 horas. Não há reflexo, mas, é importante manter atualizado. | F12: Anderson R. Tridapalli
D13: 43552 | E13: 1) Todas as funções com horas alteramos para "Sim" a coluna pequeno, médio e grande. 2) Ajustamos a pergunta "Data Privacy", adicionado um código de função ao processo. 3) Ajustamos as horas de teste piloto, processo de virada e acompanhamento pós virada. | F13: José Dallabrida
D14: 43553 | E14: 1) Ajustes do idioma das perguntas 2) Mais expressões por idioma 3) Inclusão de mais perguntas para geração da estimativa | F14: Anderson R. Tridapalli
D15: 01/Apr/2019 | E15: 1) Melhoria nas traduções 2) Incluída a pergunta de Hemodiálise Externa 3) Incluída a pergunta/orientação Protocolo de Manchester | F15: Jade Kraft
B16: 13 | C16: 09/Apr/2019 | D16: 09/Apr/2019 | E16: 1) Inclusão Digifull 2) Sugestões do Treinamentos: 2.1) Multisite - Adicionar combo box 2.2) Classificar perguntas por areas 2.3) Sepses-nova mensagem 2.4) mensagem de observação (parte de integrações) 2.5) limitação de % de gerenciamento (20% mínimo – Full 100% máximo) 2.6) limitação de número de horas referente ao projeto, conforme conversamos em reunião 2.7) validação da instalação (nao instalação do produto) 2.8) campo "fase" 1ª onda, 2ª onda em detalhe de horas 3) Inclusão NPI – Processo padrão NPI; 4) Melhorias em geral: 4.1) Corrigir idioma das respostas (Sim, Não) 4.2) Melhorar a forma de definição do Porte do Cliente e incluir opção de “Todas as funções por módulo” 4.2.1) Alterar descrição para “Porte do Cliente” 4.2.2) Adicionar a opção “Todas as funções dos módulos” 4.2.3) Adicionar coluna “Todas as funções dos módulos” na aba Base de Funções, marcando todas funções com mais de 0 horas para Sim 4.2.4) Atualizar a última versão para habilitar os portes e incluir sim ou não nas colunas dos portes na aba Base de Funções 5) Ordenar perguntas para fazerem sentido numa sequência lógica 6) Melhorar a pergunta da GQA sobre os indicadores de Sepse, Protocolo Manchester e Data Privacy 7) Indicador de alteração do Detalhe de Horas (informação diferente da planilha original com cor diferente e legenda) 8) Organizar os módulos por sequencia logica do sistema. | F16: Anderson R. Tridapalli, Diogo Benigo, José Dallabrida, Jade Kraft
B17: 14 | C17: 23/Apr/2019 | D17: 23/Apr/2019 | E17: 1) Tratado respostas em idiomas diferentes na planilha Perguntas. 2) Criada validação para respostas numéricas na planilha Perguntas. 3) Alterado a descrição das fases do projeto. 4) Melhorias em traduções 5) Inclusão do canal de vendas Philips Vendas Direta na planilha SP-PROPOSTA. 6) Alterada descrição do Deslocamento na planilha SP-PROPOSTA. 7) Alterado a descrição do campo B5 na planilha SP-PROPOSTA. | F17: Diogo Benigo
B18: 15 | C18: 43634 | D18: 43634 | E18: 1) Inclusão de horas de implantação para Gestão Populacional. 2) Inclusão de horas para clinicas pequenas e grandes. 3) Inclusão do módulo PEP/ CPOE / ADEP na Planilha Perguntas. 4) Melhorias em traduções. 5) Inclusão da Pergunta para implantação de Certificação Digital na Planilha Perguntas e acrescimo de 120h para implantação da opção. 6) Inclusão da Opção Consultório Médico (Ambulatório) na planilha Módulos. 7)Exclusão do Módulos - Call Center e funções vinculadas. Planejamento Estratégico e funções vinculadas. 8) Módulo PEP - Cadastro de Protocolos e Cadastros PEP - alterarado para 1 hora em ambos. 9) Inclusão da Pergunta "A função Gestão dos Planos Terapêuticos será utilizada em qual setor?" e opções - se "Enfermagem e Farmácia" adição (+100% de horas) 10) Alterado para 20% de acrescimo HTML5 11) Alterado Função “Laudo de Anatomia patológica” 12) Inclusa Tarja Vermelha na aba resumo: "Após preenchimento das informações prévias, atualizar o resumo com o botão direito sob a tabela da estimativa". 13) Inclusão da pasta de premissas: "Sugestões de Premissas" 14) Inclusão de Opção para aquisição de Cloud "Informações Gerais" | F18: Diogo Benigo, Anderson R. Tridapalli, Gaspar I. Borges, Fernanda Maciel, Everson Luis Faita, Antonio Peixer
B19: 16 | C19: 43643 | D19: 43634 | E19: 1) Alteração na aba Módulos - item "Prontuário Eletrônico" sai da área 'Core do sistema' e passa a pertencer ao área 'Assistencial'. 2) Alteração na aba Detalhe de Horas - Organização linear sequencial seguindo o mesmo padrão da aba Módulos. | F19: Gaspar I. Borges
B20: 17 | C20: 43656 | D20: 43634 | E20: 1) Inclusão da coluna "Observações" na aba Resumo. 2) Inclusão da coluna "Horas de Consultoria" na aba Integrações e automatização de cálculo para inclusão das horas no resumo. 3) Ajuste nas funções (REP - REP-PT - CPOE - Atendimento da Prescrição - Atendimento do lote) alteração de sugestão de inclusão em escopo por tamanho de cliente. 4) Melhorias em traduções. | F20: Gaspar I. Borges, Evandro Polastri, Anderson R. Tridapalli
B21: 18 | C21: 43692 | D21: 43634 | E21: 1) Inclusão da Pergunta "TWS -Tasy Web Suite"; 2) Inclusão de lista suspensa na aba "SP - Proposta" itém "Deslocamento" com opções; 3) Ajuste nas funções (orçamento contabil, infecção hospitalar, nutrição) alteração de sugestão de inclusão em escopo por tamanho de cliente; 4) Inclusão de Mensagens de alerta para a aplicação "TWS - Tasy Web Suite" nas abas "Módulos" e "Perguntas"; 5) Melhorias em traduções. | F21: Gaspar I. Borges
B22: 19 | C22: 43732 | D22: 43634 | E22: 1) Tradução dos Nomes das Abas para o idioma "Inglês" 2) Alteração e padronização da aba "Integrations" 3) Alteração da Pergunta "TWS" para aba "Proposal" 4) Inclusão dos campos "Modalidade" e "Valor" Cloud na aba "Proposal" 5) Inclusão da aba "TWS" 6) Inclusão do desclaimer "Em caso de oferta Java, HTML5 ou Cloud HTML5 não há possibilidade de integrações via banco de dados." na aba "Intagrations". 7) Inclusão do desclaimer "Sugestões de Premissas para serem inclusas em contrato." na aba "Assumptions Suggestion". 8) Melhorias em traduções. | F22: Gaspar I. Borges
B23: 20 | C23: 43756 | E23: 1) Retirado o aviso de aprovação necessária para projetos em HTML5; 2) Inclusa a SC - Solicitação de Contrato e informações solicitadas pelo KLAS; 3) Inseridos cálculos automáticos da proposta e do OIT; 4) Adicionado racional para inclusão de 110% nas horas caso o projeto seja Grande ou caso tenha integração/customização e/ou migração de dados. | F23: Rafael dos Santos Pellens, Gaspar l. Borges, Anderson R. Tridapalli
B24: 21 | C24: 43909 | E24: 1) Incluso aba para sugestão de horas e justificativas para Vendas e PMO na aba "Summary"; 2) Incluso campo para descrever a estratégia de implantação na aba "Summary"; 3) Incluso camos somatórios para cada sugestão (vendas e PMO) na aba "Summary"; 4) Inclusão de somatória das horas e valor hora na aba "Summary"; | F24: Rafael dos Santos Pellens
E25: Nota: Alterações relacionadas a revisões anteriores do documento não foram capturadas como parte da tabela de histórico de revisão acima e as alterações relacionadas à revisão são destacadas no próprio documento.

Sheet Version Control 
A1: 2 | B1: =HLOOKUP('General Information'!$C$6,'IDIOMA (hide)'!$A$1:$D$5016,A1,0) -> LTEP - Levantamento Técnico de Estimativa de Projeto TASY EMR Código do documento: 0060 - Rev 024
B7: Version | C7: Date | D7: Date | E7: Description | F7: Responsible
B8: 12 | C8: 01/Apr/2019 | D8: 43535 | E8: Atualizada horas de implantação, alterada algumas perguntas, criado indicador de plataforma | F8: José Dallabrida
D9: 43538 | E9: Funções com horas 0 foram removidas de todos os escopos | F9: Diogo Benigo
D10: 43539 | E10: Excluido modulo ITEM PRONTUÁRIO, funções criadas PALM | F10: Diogo Benigo
D11: 43545 | E11: Criado planilha SP- Proposta | F11: Diogo Benigo
D12: 43546 | E12: Ajustes nos módulos, funções e perguntas | F12: Diogo Benigo
D13: 43550 | E13: Adicionada a aba de Integrações | F13: Anderson R. Tridapalli
D14: 43551 | E14: 1) Ajuste do Módulo Suporte a Decisão Clínica para ser incluído no caso de Hospital de Pequeno porte; 2) Inclusão de pergunta sobre Oftalmologia para inclusão de 40 horas no Prontuário Eletrônico Paciente; 3) Ajuste do número de horas do item do PEP Oftalmologia para 40 horas. Não há reflexo, mas, é importante manter atualizado. | F14: Anderson R. Tridapalli
D15: 43552 | E15: 1) Todas as funções com horas alteramos para "Sim" a coluna pequeno, médio e grande. 2) Ajustamos a pergunta "Data Privacy", adicionado um código de função ao processo. 3) Ajustamos as horas de teste piloto, processo de virada e acompanhamento pós virada. | F15: José Dallabrida
D16: 43553 | E16: 1) Ajustes do idioma das perguntas 2) Mais expressões por idioma 3) Inclusão de mais perguntas para geração da estimativa | F16: Anderson R. Tridapalli
D17: 01/Apr/2019 | E17: 1) Melhoria nas traduções 2) Incluída a pergunta de Hemodiálise Externa 3) Incluída a pergunta/orientação Protocolo de Manchester | F17: Jade Kraft
B18: 13 | C18: 09/Apr/2019 | D18: 09/Apr/2019 | E18: 1) Inclusão Digifull 2) Sugestões do Treinamentos: 2.1) Multisite - Adicionar combo box 2.2) Classificar perguntas por areas 2.3) Sepses-nova mensagem 2.4) mensagem de observação (parte de integrações) 2.5) limitação de % de gerenciamento (20% mínimo – Full 100% máximo) 2.6) limitação de número de horas referente ao projeto, conforme conversamos em reunião 2.7) validação da instalação (nao instalação do produto) 2.8) campo "fase" 1ª onda, 2ª onda em detalhe de horas 3) Inclusão NPI – Processo padrão NPI; 4) Melhorias em geral: 4.1) Corrigir idioma das respostas (Sim, Não) 4.2) Melhorar a forma de definição do Porte do Cliente e incluir opção de “Todas as funções por módulo” 4.2.1) Alterar descrição para “Porte do Cliente” 4.2.2) Adicionar a opção “Todas as funções dos módulos” 4.2.3) Adicionar coluna “Todas as funções dos módulos” na aba Base de Funções, marcando todas funções com mais de 0 horas para Sim 4.2.4) Atualizar a última versão para habilitar os portes e incluir sim ou não nas colunas dos portes na aba Base de Funções 5) Ordenar perguntas para fazerem sentido numa sequência lógica 6) Melhorar a pergunta da GQA sobre os indicadores de Sepse, Protocolo Manchester e Data Privacy 7) Indicador de alteração do Detalhe de Horas (informação diferente da planilha original com cor diferente e legenda) 8) Organizar os módulos por sequencia logica do sistema. | F18: Anderson R. Tridapalli, Diogo Benigo, José Dallabrida, Jade Kraft
B19: 14 | C19: 23/Apr/2019 | D19: 23/Apr/2019 | E19: 1) Tratado respostas em idiomas diferentes na planilha Perguntas. 2) Criada validação para respostas numéricas na planilha Perguntas. 3) Alterado a descrição das fases do projeto. 4) Melhorias em traduções 5) Inclusão do canal de vendas Philips Vendas Direta na planilha SP-PROPOSTA. 6) Alterada descrição do Deslocamento na planilha SP-PROPOSTA. 7) Alterado a descrição do campo B5 na planilha SP-PROPOSTA. | F19: Diogo Benigo
B20: 15 | C20: 43634 | D20: 43634 | E20: 1) Inclusão de horas de implantação para Gestão Populacional. 2) Inclusão de horas para clinicas pequenas e grandes. 3) Inclusão do módulo PEP/ CPOE / ADEP na Planilha Perguntas. 4) Melhorias em traduções. 5) Inclusão da Pergunta para implantação de Certificação Digital na Planilha Perguntas e acrescimo de 120h para implantação da opção. 6) Inclusão da Opção Consultório Médico (Ambulatório) na planilha Módulos. 7)Exclusão do Módulos - Call Center e funções vinculadas. Planejamento Estratégico e funções vinculadas. 8) Módulo PEP - Cadastro de Protocolos e Cadastros PEP - alterarado para 1 hora em ambos. 9) Inclusão da Pergunta "A função Gestão dos Planos Terapêuticos será utilizada em qual setor?" e opções - se "Enfermagem e Farmácia" adição (+100% de horas) 10) Alterado para 20% de acrescimo HTML5 11) Alterado Função “Laudo de Anatomia patológica” 12) Inclusa Tarja Vermelha na aba resumo: "Após preenchimento das informações prévias, atualizar o resumo com o botão direito sob a tabela da estimativa". 13) Inclusão da pasta de premissas: "Sugestões de Premissas" 14) Inclusão de Opção para aquisição de Cloud "Informações Gerais" | F20: Diogo Benigo, Anderson R. Tridapalli, Gaspar I. Borges, Fernanda Maciel, Everson Luis Faita, Antonio Peixer
B21: 16 | C21: 43643 | D21: 43634 | E21: 1) Alteração na aba Módulos - item "Prontuário Eletrônico" sai da área 'Core do sistema' e passa a pertencer ao área 'Assistencial'. 2) Alteração na aba Detalhe de Horas - Organização linear sequencial seguindo o mesmo padrão da aba Módulos. | F21: Gaspar I. Borges
B22: 17 | C22: 43656 | D22: 43634 | E22: 1) Inclusão da coluna "Observações" na aba Resumo. 2) Inclusão da coluna "Horas de Consultoria" na aba Integrações e automatização de cálculo para inclusão das horas no resumo. 3) Ajuste nas funções (REP - REP-PT - CPOE - Atendimento da Prescrição - Atendimento do lote) alteração de sugestão de inclusão em escopo por tamanho de cliente. 4) Melhorias em traduções. | F22: Gaspar I. Borges, Evandro Polastri, Anderson R. Tridapalli
B23: 18 | C23: 43692 | D23: 43634 | E23: 1) Inclusão da Pergunta "TWS -Tasy Web Suite"; 2) Inclusão de lista suspensa na aba "SP - Proposta" itém "Deslocamento" com opções; 3) Ajuste nas funções (orçamento contabil, infecção hospitalar, nutrição) alteração de sugestão de inclusão em escopo por tamanho de cliente; 4) Inclusão de Mensagens de alerta para a aplicação "TWS - Tasy Web Suite" nas abas "Módulos" e "Perguntas"; 5) Melhorias em traduções. | F23: Gaspar I. Borges
B24: 19 | C24: 43732 | D24: 43634 | E24: 1) Tradução dos Nomes das Abas para o idioma "Inglês" 2) Alteração e padronização da aba "Integrations" 3) Alteração da Pergunta "TWS" para aba "Proposal" 4) Inclusão dos campos "Modalidade" e "Valor" Cloud na aba "Proposal" 5) Inclusão da aba "TWS" 6) Inclusão do desclaimer "Em caso de oferta Java, HTML5 ou Cloud HTML5 não há possibilidade de integrações via banco de dados." na aba "Intagrations". 7) Inclusão do desclaimer "Sugestões de Premissas para serem inclusas em contrato." na aba "Assumptions Suggestion". 8) Melhorias em traduções. | F24: Gaspar I. Borges
B25: 20 | C25: 43756 | E25: 1) Retirado o aviso de aprovação necessária para projetos em HTML5; 2) Inclusa a SC - Solicitação de Contrato e informações solicitadas pelo KLAS; 3) Inseridos cálculos automáticos da proposta e do OIT; 4) Adicionado racional para inclusão de 110% nas horas caso o projeto seja Grande ou caso tenha integração/customização e/ou migração de dados. | F25: Rafael dos Santos Pellens, Gaspar l. Borges, Anderson R. Tridapalli
B26: 21 | C26: 43909 | E26: 1) Incluso aba para sugestão de horas e justificativas para Vendas e PMO na aba "Summary"; 2) Incluso campo para descrever a estratégia de implantação na aba "Summary"; 3) Incluso camos somatórios para cada sugestão (vendas e PMO) na aba "Summary"; 4) Inclusão de somatória das horas e valor hora na aba "Summary"; | F26: Rafael dos Santos Pellens
B27: 22 | C27: 43955 | E27: 1) Inclusão das NPIs: CarePlan, Patient Journey, Tele Consulta, Contabilidade Online, Mapa Ocupação Quimioterapia, TNM, Neo Center,PEPA na aba "Questions" e "Base Funções" quando aplicável. 2) Inclusão da opção de escolha da "Moeda" em General Information; 3) Inclusão de uma quantidade de horas exclusiva para o México na aba "Base Funções"; 4) Redução dos 20% da consultoria em "Base Funções"; 5) Pequenos outros ajustes de traduções e etc. | F27: Rafael dos Santos Pellens
B28: 23 | C28: 43993 | E28: 1) Ajuste em "Modules", correções de fórmulas; 2) Ajuste em "Questions", perguntas que são específicas para um mercado, ficam como "Não Aplicáveis" para os outros idiomas; 3) Retirado o adicional de 10% para hospitais de porte grande na aba "Hours Detail"; 4) Ajustes pequenos em traduções gerais; 5) Ajuste nas fórmulas de OIT da aba "Proposal"; 6) Inclusão do valor hora de RnD na aba "Proposal". 7) Ajustes no porte da instituição em "BASE_FUNÇÕES". Antes, alguns módulos não apareciam mesmo selecionando sim em "Modules" porque não estavam previstos na aba "BASE_FUNÇÕES", agora isso foi solucionado. | F28: Rafael dos Santos Pellens
B29: 24 | E29: 1) Inclusão do produto OPS. 2) Inclusão da aba "OIT Saas" que serve para calcular automaticamente o OIT do SaaS, levando em consideração o escalonamento. 3) Inclusão da aba "Rollout" que tenta automatizar projetos que utilizarão a metodologia Rollout. 4) Inclusão da aba "Backoffice" que copia e cola informações gerais da LTEP para automatizar o preenchimento da proposta. 5) Exclusão de diversas funções que já não são mais utilizadas na aba "BASE_FUNÇÕES" 6) Revisão na aba "Questions", de forma geral, para diversas perguntas, só temos horas adicionais quando temos uma resposta acima de 1 (porque em teoria, se a resposta for 1, já temos as horas da funções previstas". Além disso, foram retiradas perguntas consideradas desnecessárias. 7) Inclusão dos NPIs: Planejamento Orçamentário, Launch Dashboard, Auditoria Concorrente 8) Revisão na aba proposal, melhorando a parte de SAAS e demais cenários. Revisão também na parte do cálculo de OIT. 10) Inclusão das modalides de Operadora; 11) Deletada a parte de integrações antiga e incluída a aba de integrações nova, com as integrações previstas; 12) Inclusão do RnD (integrações) no escopo da LTEP; 13) Revisão na aba "Questions" para que a quantiade de consultores seja gerada de acordo com o tempo de projeto desejado. 14) Adicionada a parte de escopo negativo, porém, ainda não será liberada até que tenhamos a descrição de todos os módulos em PT. | F29: Rafael dos Santos Pellens
E30: Nota: Alterações relacionadas a revisões anteriores do documento não foram capturadas como parte da tabela de histórico de revisão acima e as alterações relacionadas à revisão são destacadas no próprio documento.

Sheet Pendências
A1: Solicitante | B1: Solicitação | C1: Status | D1: Situação
A2: Fernanda | B2: Para revisão, o LTEP – 23 não está puxando o módulo de Rouparia, mesmo com o módulo selecionado no “Sim”, somente quando seleciona a opção “Todas as funções”. | C2: OK
A3: NPI | B3: 13820 Planejamento Orçamentário. | C3: OK | D3: Validar com Dallabrida quais são as funções necessárias para usar o orçamento contábil. | E3: Plano de ImplementaçãoConhecendo a função e entendendo o vínculo desta função com o Orçamento Contábil, entendemos que a função Orçamento Contábil deverá ser vendida em conjunto com esta função, assim, considerando as 40 horas do orçamento, só precisaremos manter 4 horas com esta função - em 1 semana podemos implementar ambos.
A4: NPI | B4: Processo de Launch Dashboard | C4: OK
A5: NPI | B5: Auditoria Concorrente | C5: OK | D5: Temos as horas mas não tivemos product news, não foi lançado. | E5: 2081937 | F5: 2081938
A6: NPI | B6: Portal do Beneficiário | C6: Falta código e traduções. | D6: Inserir na parte de proposta e na parte de horas. | E6: Plano de ImplementaçãoPara implementação do novo processo do Portal do Beneficiário são necessárias 32 horas. Contudo,será necessário a revisão da estimativa de OPS, retirando as funções antigas que eram usadas no Delphi e acrescendo esta nova.Para a migração de OPS (clientes da base instalada), este novo processo pode ser executado pelo cliente, sem a necessidade de alocação de um consultor, considerando-se 16 horas, pois aproveita-se o que o cliente já utilizar na plataforma em Delphi.Observações: Em ambos os casos, seja uma implantação inicial ou uma migração, o consultor somente poderá ser alocado após a conclusãoda infraestrutura necessária para rodar o portal. Relembrando que a instalação da infraestrutura para o Portal do Beneficiário rodar fica a cargo do cliente ou de um parceiro homologado Philips, e não faz parte do escopo de implantação do time de serviços(consultoria), ou seja, as horas acima não comportam o trabalho de infraestrutura.
A7: NPI | B7: Panorama Clínico | C7: OK | D7: OK. Colocamos 20 horas na nova função (painel) e não colocamos as 3 horas de ADM e 1 de cadastros gerais. | E7: Plano de implantação: Cronogramas de implantação revisados –24 horas para implementação, sendo:ADM TASY -3horasCadastros Gerais -1 horaNova função "Painel do Panorama Clínico" -20 horasInformações comerciais: Base de demonstração do Pré Vendas atualizada e disponível para demonstrações. LTEP de Vendas e Pós Vendas atualizado. Nenhuma alteração na Política e Proposta Comercial.
A8: OPS | B8: Colocar módulos e funções padrões no OPS | C8: OK | E8: Validar módulos e validar horas
A9: Fernanda | B9: • Gestão das Prescrições pela Enfermagem • Gestão das Prescrições pela Farmácia Clínica • SAE – Sistematização da Assistência de Enfermagem • Laudo Paciente | C9: Pendente | E9: As duas últimas OK, as 2 primeiras validar com RnD.
A10: OPS | B10: 1 – Haverá acompanhamento do monitoramento ANS? (acrescer 40 horas), normalmente o envio do primeiro monitoramento ocorre 2 meses após a virada. | C10: OK
A11: OPS | B11: 2 – Haverá acompanhamento para o SIP? (acrescer 40 horas), normalmente o envio do primeiro SIP ocorre 4 meses após a virada. | C11: OK
A12: OPS | B12: 3 – Haverá acompanhamento para o DIOPS e geração livros auxiliares para auditoria? (acrescer 80 horas), normalmente o envio do primeiro DIOPS ocorre 4 meses após a virada. | C12: OK
A13: OPS | B13: 5 – Quantidade de beneficiários? (aumentar 20% das horas do projeto a cada 80.000) | C13: Pendente
A14: OPS | B14: HDM? | C14: OK
A15: OPS | B15: Funções exclusivas Unimed | C15: OK | D15: Todas as funções que são exclusivas Unimed tem que estrar como No na autogestão e med grupo
A16: Fernanda | B16: 4Test (Função só p/ Java) Schematic4Test (Função só p/ HTML5) | C16: Pendente | D16: Confirmado com Dallabrida, colocar dessa forma nas horas.

Sheet General Information
A1: 2 | B1: =HLOOKUP($C$6,'IDIOMA (hide)'!$A$1:$D$5016,A1,0) -> LTEP - Levantamento Técnico de Estimativa de Projeto TASY EMR Código do documento: 0060 - Rev 024
A2: 3 | B2: =HLOOKUP($C$6,'IDIOMA (hide)'!$A$1:$D$5016,A2,0) -> General Information | D2: OCULTAR
A4: 5 | B4: =HLOOKUP($C$6,'IDIOMA (hide)'!$A$1:$D$5016,A4,0) -> País | G4: =IF(C$4="Brasil","Guia de Segmentação (Para Brasil)","")
B5: =IF(OR(C4="Outro",C4="Other",C4="Otro")=TRUE,HLOOKUP($C$6,'IDIOMA (hide)'!$A$1:$D$5016,A5,0),HLOOKUP($C$6,'IDIOMA (hide)'!$A$1:$D$5016,A7,0)) -> Não Preencher | G5: =IF($C$4="Brasil","Hospitais","")
A6: 40 | B6: =HLOOKUP($C$6,'IDIOMA (hide)'!$A$1:$D$5016,A6,0) -> Idioma | C6: Português | G6: =IF($C$4="Brasil","Pequeno","") | H6: =IF($C$4="Brasil","Até 100 Leitos","")
A7: 361 | B7: =HLOOKUP($C$6,'IDIOMA (hide)'!$A$1:$D$5016,E8,0) -> Moeda | G7: =IF($C$4="Brasil","Médio","") | H7: =IF($C$4="Brasil","De 101 até 300 Leitos","")
E8: 480 | G8: =IF($C$4="Brasil","Grande","") | H8: =IF($C$4="Brasil","De 301 até 500 Leitos","")
A9: 6 | B9: =HLOOKUP($C$6,'IDIOMA (hide)'!$A$1:$D$5016,A9,0) -> Informações do Cliente | C9: =HLOOKUP($C$6,'IDIOMA (hide)'!$A$1:$D$5016,B9,0) -> #REF! | G9: =IF($C$4="Brasil","Gigante","") | H9: =IF($C$4="Brasil","Acima de 500 Leitos","")
A10: 7 | B10: =HLOOKUP($C$6,'IDIOMA (hide)'!$A$1:$D$5016,A10,0) -> ID Oportunidade | G10: =IF($C$4="Brasil","OPS - Operadoras de Saúde","")
A11: 8 | B11: =HLOOKUP($C$6,'IDIOMA (hide)'!$A$1:$D$5016,A11,0) -> Nome do Cliente | G11: =IF($C$4="Brasil","Pequeno","") | H11: =IF($C$4="Brasil","Menos de 20 mil vidas","")
A12: 9 | B12: =HLOOKUP($C$6,'IDIOMA (hide)'!$A$1:$D$5016,A12,0) -> Contato | G12: =IF($C$4="Brasil","Médio","") | H12: =IF($C$4="Brasil","De 20 a 100 mil vidas","")
A13: 13 | B13: =HLOOKUP($C$6,'IDIOMA (hide)'!$A$1:$D$5016,A13,0) -> Número de Leitos | G13: =IF($C$4="Brasil","Grande","") | H13: =IF($C$4="Brasil","Acima de 100 mil vidas","")
A14: 409 | B14: =HLOOKUP($C$6,'IDIOMA (hide)'!$A$1:$D$5016,A14,0) -> Sistema anterior (a ser substituído) | G14: =IF($C$4="Brasil","Clínicas","")
A15: 504 | B15: =HLOOKUP($C$6,'IDIOMA (hide)'!$A$1:$D$5016,A15,0) -> Será uma proposta no Modelo Trade In? | E15: 200 | G15: =IF($C$4="Brasil","Pequena","") | H15: =IF($C$4="Brasil","Até 2 Unidades / Faturamento até 5 M/Ano","")
A16: 76 | B16: =HLOOKUP($C$6,'IDIOMA (hide)'!$A$1:$D$5016,A16,0) -> Funções sugeridas pelo porte do cliente | D16: =IF(OR(C16='Listas (Hide)'!D5,C16='Listas (Hide)'!B5,C16='Listas (Hide)'!C5)=TRUE,1,IF(OR(C16='Listas (Hide)'!D6,C16='Listas (Hide)'!B6,C16='Listas (Hide)'!C6)=TRUE,2,IF(OR(C16='Listas (Hide)'!D7,C16='Listas (Hide)'!B7,C16='Listas (Hide)'!C7)=TRUE,3,IF(OR(C16='Listas (Hide)'!D8,C16='Listas (Hide)'!B8,C16='Listas (Hide)'!C8)=TRUE,4,IF(OR(C16='Listas (Hide)'!D9,C16='Listas (Hide)'!B9,C16='Listas (Hide)'!C9)=TRUE,5,IF(OR(C16='Listas (Hide)'!D10,C16='Listas (Hide)'!B10,C16='Listas (Hide)'!C10)=TRUE,6,IF(C16='Listas (Hide)'!B11,7,IF(C16='Listas (Hide)'!B12,8,IF(C16='Listas (Hide)'!B13,9,"Erro"))))))))) -> Erro | E16: =HLOOKUP($C$6,'IDIOMA (hide)'!$A$1:$D$5016,E15,0) -> *Campo Obrigatório para gerar estimativa | G16: =IF($C$4="Brasil","Médio","") | H16: =IF($C$4="Brasil","De 3 a 6 Unidades / Faturamento de 5 a 20 M/Ano","")
A17: 505 | B17: =HLOOKUP($C$6,'IDIOMA (hide)'!$A$1:$D$5016,A17,0) -> Funções Sugeridas pela modalidade (OPS) | D17: =IF(OR(C17='Listas (Hide)'!D5,C17='Listas (Hide)'!B5,C17='Listas (Hide)'!C5)=TRUE,1,IF(OR(C17='Listas (Hide)'!D6,C17='Listas (Hide)'!B6,C17='Listas (Hide)'!C6)=TRUE,2,IF(OR(C17='Listas (Hide)'!D7,C17='Listas (Hide)'!B7,C17='Listas (Hide)'!C7)=TRUE,3,IF(OR(C17='Listas (Hide)'!D8,C17='Listas (Hide)'!B8,C17='Listas (Hide)'!C8)=TRUE,4,IF(OR(C17='Listas (Hide)'!D9,C17='Listas (Hide)'!B9,C17='Listas (Hide)'!C9)=TRUE,5,IF(OR(C17='Listas (Hide)'!D10,C17='Listas (Hide)'!B10,C17='Listas (Hide)'!C10)=TRUE,6,IF(C17='Listas (Hide)'!B11,7,IF(C17='Listas (Hide)'!B12,8,IF(C17='Listas (Hide)'!B13,9,"Erro"))))))))) -> Erro | E17: =HLOOKUP($C$6,'IDIOMA (hide)'!$A$1:$D$5016,E15,0) -> *Campo Obrigatório para gerar estimativa
A18: 506 | B18: =HLOOKUP($C$6,'IDIOMA (hide)'!$A$1:$D$5016,A18,0) -> Produto | G18: =IF($C$4="Brasil","Grande","") | H18: =IF($C$4="Brasil","Acima de 7 Unidades / Faturamento acima de 20 M/Ano","")
A19: 199 | B19: =HLOOKUP($C$6,'IDIOMA (hide)'!$A$1:$D$5016,A19,0) -> Plataforma
A20: 345 | B20: =HLOOKUP($C$6,'IDIOMA (hide)'!$A$1:$D$5016,A20,0) -> Oferta Cloud / SaaS / Nuvem

Sheet Proposal
A1: 2 | B1: =HLOOKUP('General Information'!$C$6,'IDIOMA (hide)'!$A$1:$D$5016,A1,0) -> LTEP - Levantamento Técnico de Estimativa de Projeto TASY EMR Código do documento: 0060 - Rev 024
A3: 198 | B3: =HLOOKUP('General Information'!$C$6,'IDIOMA (hide)'!$A$1:$D$5016,A3,0) -> SP - Solicitação de Proposta
A4: 160 | B4: =HLOOKUP('General Information'!$C$6,'IDIOMA (hide)'!$A$1:$D$5016,A4,0) -> Informações Gerais
A7: 141 | B7: =HLOOKUP('General Information'!$C$6,'IDIOMA (hide)'!$A$1:$D$5016,A7,0) -> Informações sobre o Cliente
A8: 77 | B8: =HLOOKUP('General Information'!$C$6,'IDIOMA (hide)'!$A$1:$D$5016,A8,0) -> CNPJ
A9: 79 | B9: =HLOOKUP('General Information'!$C$6,'IDIOMA (hide)'!$A$1:$D$5016,A9,0) -> Razão Social
A10: 80 | B10: =HLOOKUP('General Information'!$C$6,'IDIOMA (hide)'!$A$1:$D$5016,A10,0) -> Nome Fantasia
A11: 81 | B11: =HLOOKUP('General Information'!$C$6,'IDIOMA (hide)'!$A$1:$D$5016,A11,0) -> Tipo de Proposta
A12: 82 | B12: =HLOOKUP('General Information'!$C$6,'IDIOMA (hide)'!$A$1:$D$5016,A12,0) -> Forma de Licenciamento
A13: 83 | B13: =HLOOKUP('General Information'!$C$6,'IDIOMA (hide)'!$A$1:$D$5016,A13,0) -> Número de Licenças
A14: 471 | B14: =HLOOKUP('General Information'!$C$6,'IDIOMA (hide)'!$A$1:$D$5016,A14,0) -> Qual template de proposta deseja receber?
A15: 161 | B15: =HLOOKUP('General Information'!$C$6,'IDIOMA (hide)'!$A$1:$D$5016,A15,0) -> Dados Comerciais
B18: Informações Gerais e Condições de Pgto | E18: Cálculo OIT
A19: 427 | B19: =HLOOKUP('General Information'!$C$6,'IDIOMA (hide)'!$A$1:$D$5016,A19,0) -> Vigência do Contrato | D19: 419 | E19: =HLOOKUP('General Information'!$C$6,'IDIOMA (hide)'!$A$1:$D$5016,D19,0) -> Tipo de Venda | F19: Philips
A20: 428 | B20: =HLOOKUP('General Information'!$C$6,'IDIOMA (hide)'!$A$1:$D$5016,A20,0) -> Carência na Manutenção (em meses) | D20: 420 | E20: =HLOOKUP('General Information'!$C$6,'IDIOMA (hide)'!$A$1:$D$5016,D20,0) -> Licença | F20: =IF(C11="CDU/SaaP",C23*C13,IF(C11="LUT/SAAS","0",IF(OR(C11="CDU+LUT",OR(C11="CDU+LUT+Cloud"),OR(C11="CDU+Cloud")),C23*C13,0))) -> 0
A21: 90 | B21: =HLOOKUP('General Information'!$C$6,'IDIOMA (hide)'!$A$1:$D$5016,A21,0) -> Os impostos estão inclusos no valor hora? | E21: =HLOOKUP('General Information'!$C$6,'IDIOMA (hide)'!$A$1:$D$5016,D23,0) -> Consultoria | F21: =Rollout!AE18*Proposal!C32 -> 0
A22: 492 | B22: =HLOOKUP('General Information'!$C$6,'IDIOMA (hide)'!$A$1:$D$5016,A22,0) -> Proposta - CDU | E22: =HLOOKUP('General Information'!$C$6,'IDIOMA (hide)'!$A$1:$D$5016,D24,0) -> Gerenciamento de Projeto | F22: =Rollout!AE19*Proposal!C33 -> 0
A23: 86 | B23: =HLOOKUP('General Information'!$C$6,'IDIOMA (hide)'!$A$1:$D$5016,A23,0) -> Valor CDU | D23: 422 | E23: =HLOOKUP('General Information'!$C$6,'IDIOMA (hide)'!$A$1:$D$5016,D25,0) -> R&D | F23: =IF(C34="",0,(Rollout!AE20*C34)) -> 0
A24: 87 | B24: =HLOOKUP('General Information'!$C$6,'IDIOMA (hide)'!$A$1:$D$5016,A24,0) -> Valor da Manutenção | D24: 423 | E24: =HLOOKUP('General Information'!$C$6,'IDIOMA (hide)'!$A$1:$D$5016,D26,0) -> Manutenção | F24: =IF(C11="CDU/SaaP",C24*C13*(C19-C20),IF(C11="LUT/SaaS",(C13*C30*C19),IF(C11="LUT+Cloud",C29*C19,IF(C11="SaaS (Cloud)",'OIT SaaS'!#REF!,IF(OR(C11="CDU+LUT",OR(C11="CDU+LUT+Cloud"),OR(C11="CDU+Cloud")),(C24*C13)*(C19-C20),0))))) -> 0
A25: 417 | B25: =HLOOKUP('General Information'!$C$6,'IDIOMA (hide)'!$A$1:$D$5016,A25,0) -> Valor Total Manutenção CDU (Mensal) | C25: =C24*C13 -> 0 | D25: 424 | E25: =HLOOKUP('General Information'!$C$6,'IDIOMA (hide)'!$A$1:$D$5016,D28,0) -> OIT | F25: =IF(F19="Channel",F20+F24+F23,IF(F19="Philips",F20+F24+F21+F22+F23,"")) -> 0
A26: 91 | B26: =HLOOKUP('General Information'!$C$6,'IDIOMA (hide)'!$A$1:$D$5016,A26,0) -> Parcelas? (Quantidade) | D26: 421 | E26: =HLOOKUP('General Information'!$C$6,'IDIOMA (hide)'!$A$1:$D$5016,D29,0) -> Taxa | F26: =F25-'Listas (Hide)'!B129 -> 0
A27: 533 | B27: =HLOOKUP('General Information'!$C$6,'IDIOMA (hide)'!$A$1:$D$5016,A27,0) -> Valor por Parcela | C27: =IFERROR((C23*C13)/C26,0) -> 0
A28: 493 | B28: =HLOOKUP('General Information'!$C$6,'IDIOMA (hide)'!$A$1:$D$5016,A28,0) -> Proposta - LUT | D28: 425
A29: 85 | B29: =HLOOKUP('General Information'!$C$6,'IDIOMA (hide)'!$A$1:$D$5016,A29,0) -> Valor da LUT | D29: 426
A30: 418 | B30: =HLOOKUP('General Information'!$C$6,'IDIOMA (hide)'!$A$1:$D$5016,A30,0) -> Valor Total da Manutenção LUT (Mensal) | C30: =C29*C13 -> 0
A31: 494 | B31: =HLOOKUP('General Information'!$C$6,'IDIOMA (hide)'!$A$1:$D$5016,A31,0) -> Proposta - Serviços
A32: 88 | B32: =HLOOKUP('General Information'!$C$6,'IDIOMA (hide)'!$A$1:$D$5016,A32,0) -> Valor da Hora da Consultoria
A33: 89 | B33: =HLOOKUP('General Information'!$C$6,'IDIOMA (hide)'!$A$1:$D$5016,A33,0) -> Valor Hora de Gerenciamento De Projetos
A34: 490 | B34: =HLOOKUP('General Information'!$C$6,'IDIOMA (hide)'!$A$1:$D$5016,A34,0) -> Valor Hora RnD
A35: 495 | B35: =HLOOKUP('General Information'!$C$6,'IDIOMA (hide)'!$A$1:$D$5016,A35,0) -> Proposta - SaaS (Cloud)
A36: 497 | B36: =HLOOKUP('General Information'!$C$6,'IDIOMA (hide)'!$A$1:$D$5016,A36,0) -> Valor Base SaaS (Pacote 20 Usuários) | D36: 363
A37: 498 | B37: =HLOOKUP('General Information'!$C$6,'IDIOMA (hide)'!$A$1:$D$5016,A37,0) -> Valor das Licenças Adicionais (Por Licença)
A38: 499 | B38: =HLOOKUP('General Information'!$C$6,'IDIOMA (hide)'!$A$1:$D$5016,A38,0) -> Valor Mensal Total SaaS (Cloud) | C38: =IF(C13<101,(C36+((C13-20)*C37)),C37*C13) -> 0
A39: 507 | B39: =HLOOKUP('General Information'!$C$6,'IDIOMA (hide)'!$A$1:$D$5016,A39,0) -> Propostas Adicionais
A40: 508 | B40: =HLOOKUP('General Information'!$C$6,'IDIOMA (hide)'!$A$1:$D$5016,A40,0) -> TWS - Portal do Paciente
A41: 509 | B41: =HLOOKUP('General Information'!$C$6,'IDIOMA (hide)'!$A$1:$D$5016,A41,0) -> Incluir TWS nesta proposta?
A42: 510 | B42: =HLOOKUP('General Information'!$C$6,'IDIOMA (hide)'!$A$1:$D$5016,A42,0) -> Porte | D42: 354
A43: 511 | B43: =HLOOKUP('General Information'!$C$6,'IDIOMA (hide)'!$A$1:$D$5016,A43,0) -> Valor do TWS
A44: 357 | B44: =HLOOKUP('General Information'!$C$6,'IDIOMA (hide)'!$A$1:$D$5016,A44,0) -> Horas de Consultoria | C44: =IF(C41="Yes",80,0) -> 0
B45: Protocolo de Manchester
...

Sheet OIT SaaS
A1: 2 | C1: =HLOOKUP('General Information'!$C$6,'IDIOMA (hide)'!$A$1:$D$5016,A1,0) -> LTEP - Levantamento Técnico de Estimativa de Projeto TASY EMR Código do documento: 0060 - Rev 024
A3: 198 | C3: =HLOOKUP('General Information'!$C$6,'IDIOMA (hide)'!$A$1:$D$5016,A3,0) -> SP - Solicitação de Proposta
A4: 160 | B4: =HLOOKUP('General Information'!$C$6,'IDIOMA (hide)'!$A$1:$D$5016,A4,0) -> Informações Gerais
A5: 357 | B5: =HLOOKUP('General Information'!$C$6,'IDIOMA (hide)'!$A$1:$D$5016,A5,0) -> Horas de Consultoria | C5: =GETPIVOTDATA("TOTAL HOURS (STANDARD HOURS + ADDITIONAL HOURS)",Summary!$B$13) -> 232 | D5: =HLOOKUP('General Information'!$C$6,'IDIOMA (hide)'!$A$1:$D$5016,A6,0) -> Qtd Consultores | E5: =Proposal!B38 -> Valor Mensal Total SaaS (Cloud) | H5: Month | I5: Hours | J5: Price | K5: Months
A6: 514 | D6: =Questions!D145 -> 1 | H6: 1 | I6: =IF(H6<>"",IF(H6<$K$6,($C$5/$K$6)*H6,IF(H6=$K$6,($C$5+0),IF(H6>$K$6,($C$5+0),""))),"") -> 160 | J6: =IF(H6<>"",IF(I6<$K$10,E$7*30%,IF(AND(I6>$K$8,I6<$K$12),$E$7*60%,IF(I6>=$K$12,$E$7*100%,""))),"") -> 0 | K6: =D7 -> 1.45 | L6: <- Qtd de meses considerando a qtd de consultores informados (1 trabalha 160)
D7: =C5/(160*D6) -> 1.45 | E7: =Proposal!C38 -> 0 | H7: 2 | I7: =IF(H7<>"",IF(H7<$K$6,($C$5/$K$6)*H7,IF(H7=$K$6,($C$5+0),IF(H7>$K$6,($C$5+0),""))),"") -> 232 | J7: =IF(H7<>"",IF(I7<$K$10,E$7*30%,IF(AND(I7>$K$8,I7<$K$12),$E$7*60%,IF(I7>=$K$12,$E$7*100%,""))),"") -> 0 | K7: Parametrization (30%)
H8: 3 | I8: =IF(H8<>"",IF(H8<$K$6,($C$5/$K$6)*H8,IF(H8=$K$6,($C$5+0),IF(H8>$K$6,($C$5+0),""))),"") -> 232 | J8: =IF(H8<>"",IF(I8<$K$10,E$7*30%,IF(AND(I8>$K$8,I8<$K$12),$E$7*60%,IF(I8>=$K$12,$E$7*100%,""))),"") -> 0 | K8: =C5*30% -> 69.6 | L8: <- Quantidade de horas correspondente a 30% do total da implantação
H9: 4 | I9: =IF(H9<>"",IF(H9<$K$6,($C$5/$K$6)*H9,IF(H9=$K$6,($C$5+0),IF(H9>$K$6,($C$5+0),""))),"") -> 232 | J9: =IF(H9<>"",IF(I9<$K$10,E$7*30%,IF(AND(I9>$K$8,I9<$K$12),$E$7*60%,IF(I9>=$K$12,$E$7*100%,""))),"") -> 0 | K9: Pilot Test (60%)
H10: 5 | I10: =IF(H10<>"",IF(H10<$K$6,($C$5/$K$6)*H10,IF(H10=$K$6,($C$5+0),IF(H10>$K$6,($C$5+0),""))),"") -> 232 | J10: =IF(H10<>"",IF(I10<$K$10,E$7*30%,IF(AND(I10>$K$8,I10<$K$12),$E$7*60%,IF(I10>=$K$12,$E$7*100%,""))),"") -> 0 | K10: =C5*60% -> 139.2 | L10: <- Quantidade de horas correspondente a 60% do total da implantação
D11: =H66 -> Total | E11: =J66 -> 0 | H11: 6 | I11: =IF(H11<>"",IF(H11<$K$6,($C$5/$K$6)*H11,IF(H11=$K$6,($C$5+0),IF(H11>$K$6,($C$5+0),""))),"") -> 232 | J11: =IF(H11<>"",IF(I11<$K$10,E$7*30%,IF(AND(I11>$K$8,I11<$K$12),$E$7*60%,IF(I11>=$K$12,$E$7*100%,""))),"") -> 0 | K11: Go-Live (100%)
H12: 7 | I12: =IF(H12<>"",IF(H12<$K$6,($C$5/$K$6)*H12,IF(H12=$K$6,($C$5+0),IF(H12>$K$6,($C$5+0),""))),"") -> 232 | J12: =IF(H12<>"",IF(I12<$K$10,E$7*30%,IF(AND(I12>$K$8,I12<$K$12),$E$7*60%,IF(I12>=$K$12,$E$7*100%,""))),"") -> 0 | K12: =C5*100% -> 232 | L12: <- Quantidade de horas correspondente a 100% do total da implantação
H13: 8 | I13: =IF(H13<>"",IF(H13<$K$6,($C$5/$K$6)*H13,IF(H13=$K$6,($C$5+0),IF(H13>$K$6,($C$5+0),""))),"") -> 232 | J13: =IF(H13<>"",IF(I13<$K$10,E$7*30%,IF(AND(I13>$K$8,I13<$K$12),$E$7*60%,IF(I13>=$K$12,$E$7*100%,""))),"") -> 0
H14: 9 | I14: =IF(H14<>"",IF(H14<$K$6,($C$5/$K$6)*H14,IF(H14=$K$6,($C$5+0),IF(H14>$K$6,($C$5+0),""))),"") -> 232 | J14: =IF(H14<>"",IF(I14<$K$10,E$7*30%,IF(AND(I14>$K$8,I14<$K$12),$E$7*60%,IF(I14>=$K$12,$E$7*100%,""))),"") -> 0 | K14: OIT
H15: 10 | I15: =IF(H15<>"",IF(H15<$K$6,($C$5/$K$6)*H15,IF(H15=$K$6,($C$5+0),IF(H15>$K$6,($C$5+0),""))),"") -> 232 | J15: =IF(H15<>"",IF(I15<$K$10,E$7*30%,IF(AND(I15>$K$8,I15<$K$12),$E$7*60%,IF(I15>=$K$12,$E$7*100%,""))),"") -> 0 | K15: =SUM(J6:J65) -> 0
H16: 11 | I16: =IF(H16<>"",IF(H16<$K$6,($C$5/$K$6)*H16,IF(H16=$K$6,($C$5+0),IF(H16>$K$6,($C$5+0),""))),"") -> 232 | J16: =IF(H16<>"",IF(I16<$K$10,E$7*30%,IF(AND(I16>$K$8,I16<$K$12),$E$7*60%,IF(I16>=$K$12,$E$7*100%,""))),"") -> 0
H17: 12 | I17: =IF(H17<>"",IF(H17<$K$6,($C$5/$K$6)*H17,IF(H17=$K$6,($C$5+0),IF(H17>$K$6,($C$5+0),""))),"") -> 232 | J17: =IF(H17<>"",IF(I17<$K$10,E$7*30%,IF(AND(I17>$K$8,I17<$K$12),$E$7*60%,IF(I17>=$K$12,$E$7*100%,""))),"") -> 0
H18: =IF(Proposal!$C$19>12,'OIT SaaS'!H17+1,"") | I18: =IF(H18<>"",IF(H18<$K$6,($C$5/$K$6)*H18,IF(H18=$K$6,($C$5+0),IF(H18>$K$6,($C$5+0),""))),"") | J18: =IF(H18<>"",IF(I18<$K$10,E$7*30%,IF(AND(I18>$K$8,I18<$K$12),$E$7*60%,IF(I18>=$K$12,$E$7*100%,""))),"")
H19: =IF(Proposal!$C$19>12,'OIT SaaS'!H18+1,"") | I19: =IF(H19<>"",IF(H19<$K$6,($C$5/$K$6)*H19,IF(H19=$K$6,($C$5+0),IF(H19>$K$6,($C$5+0),""))),"") | J19: =IF(H19<>"",IF(I19<$K$10,E$7*30%,IF(AND(I19>$K$8,I19<$K$12),$E$7*60%,IF(I19>=$K$12,$E$7*100%,""))),"")
H20: =IF(Proposal!$C$19>12,'OIT SaaS'!H19+1,"") | I20: =IF(H20<>"",IF(H20<$K$6,($C$5/$K$6)*H20,IF(H20=$K$6,($C$5+0),IF(H20>$K$6,($C$5+0),""))),"") | J20: =IF(H20<>"",IF(I20<$K$10,E$7*30%,IF(AND(I20>$K$8,I20<$K$12),$E$7*60%,IF(I20>=$K$12,$E$7*100%,""))),"")
H21: =IF(Proposal!$C$19>12,'OIT SaaS'!H20+1,"") | I21: =IF(H21<>"",IF(H21<$K$6,($C$5/$K$6)*H21,IF(H21=$K$6,($C$5+0),IF(H21>$K$6,($C$5+0),""))),"") | J21: =IF(H21<>"",IF(I21<$K$10,E$7*30%,IF(AND(I21>$K$8,I21<$K$12),$E$7*60%,IF(I21>=$K$12,$E$7*100%,""))),"")
H22: =IF(Proposal!$C$19>12,'OIT SaaS'!H21+1,"") | I22: =IF(H22<>"",IF(H22<$K$6,($C$5/$K$6)*H22,IF(H22=$K$6,($C$5+0),IF(H22>$K$6,($C$5+0),""))),"") | J22: =IF(H22<>"",IF(I22<$K$10,E$7*30%,IF(AND(I22>$K$8,I22<$K$12),$E$7*60%,IF(I22>=$K$12,$E$7*100%,""))),"")
H23: =IF(Proposal!$C$19>12,'OIT SaaS'!H22+1,"") | I23: =IF(H23<>"",IF(H23<$K$6,($C$5/$K$6)*H23,IF(H23=$K$6,($C$5+0),IF(H23>$K$6,($C$5+0),""))),"") | J23: =IF(H23<>"",IF(I23<$K$10,E$7*30%,IF(AND(I23>$K$8,I23<$K$12),$E$7*60%,IF(I23>=$K$12,$E$7*100%,""))),"")
H24: =IF(Proposal!$C$19>12,'OIT SaaS'!H23+1,"") | I24: =IF(H24<>"",IF(H24<$K$6,($C$5/$K$6)*H24,IF(H24=$K$6,($C$5+0),IF(H24>$K$6,($C$5+0),""))),"") | J24: =IF(H24<>"",IF(I24<$K$10,E$7*30%,IF(AND(I24>$K$8,I24<$K$12),$E$7*60%,IF(I24>=$K$12,$E$7*100%,""))),"")
H25: =IF(Proposal!$C$19>12,'OIT SaaS'!H24+1,"") | I25: =IF(H25<>"",IF(H25<$K$6,($C$5/$K$6)*H25,IF(H25=$K$6,($C$5+0),IF(H25>$K$6,($C$5+0),""))),"") | J25: =IF(H25<>"",IF(I25<$K$10,E$7*30%,IF(AND(I25>$K$8,I25<$K$12),$E$7*60%,IF(I25>=$K$12,$E$7*100%,""))),"")
H26: =IF(Proposal!$C$19>12,'OIT SaaS'!H25+1,"") | I26: =IF(H26<>"",IF(H26<$K$6,($C$5/$K$6)*H26,IF(H26=$K$6,($C$5+0),IF(H26>$K$6,($C$5+0),""))),"") | J26: =IF(H26<>"",IF(I26<$K$10,E$7*30%,IF(AND(I26>$K$8,I26<$K$12),$E$7*60%,IF(I26>=$K$12,$E$7*100%,""))),"")
H27: =IF(Proposal!$C$19>12,'OIT SaaS'!H26+1,"") | I27: =IF(H27<>"",IF(H27<$K$6,($C$5/$K$6)*H27,IF(H27=$K$6,($C$5+0),IF(H27>$K$6,($C$5+0),""))),"") | J27: =IF(H27<>"",IF(I27<$K$10,E$7*30%,IF(AND(I27>$K$8,I27<$K$12),$E$7*60%,IF(I27>=$K$12,$E$7*100%,""))),"")
H28: =IF(Proposal!$C$19>12,'OIT SaaS'!H27+1,"") | I28: =IF(H28<>"",IF(H28<$K$6,($C$5/$K$6)*H28,IF(H28=$K$6,($C$5+0),IF(H28>$K$6,($C$5+0),""))),"") | J28: =IF(H28<>"",IF(I28<$K$10,E$7*30%,IF(AND(I28>$K$8,I28<$K$12),$E$7*60%,IF(I28>=$K$12,$E$7*100%,""))),"")
H29: =IF(Proposal!$C$19>12,'OIT SaaS'!H28+1,"") | I29: =IF(H29<>"",IF(H29<$K$6,($C$5/$K$6)*H29,IF(H29=$K$6,($C$5+0),IF(H29>$K$6,($C$5+0),""))),"") | J29: =IF(H29<>"",IF(I29<$K$10,E$7*30%,IF(AND(I29>$K$8,I29<$K$12),$E$7*60%,IF(I29>=$K$12,$E$7*100%,""))),"")
H30: =IF(Proposal!$C$19>24,'OIT SaaS'!H29+1,"") | I30: =IF(H30<>"",IF(H30<$K$6,($C$5/$K$6)*H30,IF(H30=$K$6,($C$5+0),IF(H30>$K$6,($C$5+0),""))),"") | J30: =IF(H30<>"",IF(I30<$K$10,E$7*30%,IF(AND(I30>$K$8,I30<$K$12),$E$7*60%,IF(I30>=$K$12,$E$7*100%,""))),"")
H31: =IF(Proposal!$C$19>24,'OIT SaaS'!H30+1,"") | I31: =IF(H31<>"",IF(H31<$K$6,($C$5/$K$6)*H31,IF(H31=$K$6,($C$5+0),IF(H31>$K$6,($C$5+0),""))),"") | J31: =IF(H31<>"",IF(I31<$K$10,E$7*30%,IF(AND(I31>$K$8,I31<$K$12),$E$7*60%,IF(I31>=$K$12,$E$7*100%,""))),"")
H32: =IF(Proposal!$C$19>24,'OIT SaaS'!H31+1,"") | I32: =IF(H32<>"",IF(H32<$K$6,($C$5/$K$6)*H32,IF(H32=$K$6,($C$5+0),IF(H32>$K$6,($C$5+0),""))),"") | J32: =IF(H32<>"",IF(I32<$K$10,E$7*30%,IF(AND(I32>$K$8,I32<$K$12),$E$7*60%,IF(I32>=$K$12,$E$7*100%,""))),"")
H33: =IF(Proposal!$C$19>24,'OIT SaaS'!H32+1,"") | I33: =IF(H33<>"",IF(H33<$K$6,($C$5/$K$6)*H33,IF(H33=$K$6,($C$5+0),IF(H33>$K$6,($C$5+0),""))),"") | J33: =IF(H33<>"",IF(I33<$K$10,E$7*30%,IF(AND(I33>$K$8,I33<$K$12),$E$7*60%,IF(I33>=$K$12,$E$7*100%,""))),"")
H34: =IF(Proposal!$C$19>24,'OIT SaaS'!H33+1,"") | I34: =IF(H34<>"",IF(H34<$K$6,($C$5/$K$6)*H34,IF(H34=$K$6,($C$5+0),IF(H34>$K$6,($C$5+0),""))),"") | J34: =IF(H34<>"",IF(I34<$K$10,E$7*30%,IF(AND(I34>$K$8,I34<$K$12),$E$7*60%,IF(I34>=$K$12,$E$7*100%,""))),"")
H35: =IF(Proposal!$C$19>24,'OIT SaaS'!H34+1,"") | I35: =IF(H35<>"",IF(H35<$K$6,($C$5/$K$6)*H35,IF(H35=$K$6,($C$5+0),IF(H35>$K$6,($C$5+0),""))),"") | J35: =IF(H35<>"",IF(I35<$K$10,E$7*30%,IF(AND(I35>$K$8,I35<$K$12),$E$7*60%,IF(I35>=$K$12,$E$7*100%,""))),"")
H36: =IF(Proposal!$C$19>24,'OIT SaaS'!H35+1,"") | I36: =IF(H36<>"",IF(H36<$K$6,($C$5/$K$6)*H36,IF(H36=$K$6,($C$5+0),IF(H36>$K$6,($C$5+0),""))),"") | J36: =IF(H36<>"",IF(I36<$K$10,E$7*30%,IF(AND(I36>$K$8,I36<$K$12),$E$7*60%,IF(I36>=$K$12,$E$7*100%,""))),"")
H37: =IF(Proposal!$C$19>24,'OIT SaaS'!H36+1,"") | I37: =IF(H37<>"",IF(H37<$K$6,($C$5/$K$6)*H37,IF(H37=$K$6,($C$5+0),IF(H37>$K$6,($C$5+0),""))),"") | J37: =IF(H37<>"",IF(I37<$K$10,E$7*30%,IF(AND(I37>$K$8,I37<$K$12),$E$7*60%,IF(I37>=$K$12,$E$7*100%,""))),"")
H38: =IF(Proposal!$C$19>24,'OIT SaaS'!H37+1,"") | I38: =IF(H38<>"",IF(H38<$K$6,($C$5/$K$6)*H38,IF(H38=$K$6,($C$5+0),IF(H38>$K$6,($C$5+0),""))),"") | J38: =IF(H38<>"",IF(I38<$K$10,E$7*30%,IF(AND(I38>$K$8,I38<$K$12),$E$7*60%,IF(I38>=$K$12,$E$7*100%,""))),"")
H39: =IF(Proposal!$C$19>24,'OIT SaaS'!H38+1,"") | I39: =IF(H39<>"",IF(H39<$K$6,($C$5/$K$6)*H39,IF(H39=$K$6,($C$5+0),IF(H39>$K$6,($C$5+0),""))),"") | J39: =IF(H39<>"",IF(I39<$K$10,E$7*30%,IF(AND(I39>$K$8,I39<$K$12),$E$7*60%,IF(I39>=$K$12,$E$7*100%,""))),"")
H40: =IF(Proposal!$C$19>24,'OIT SaaS'!H39+1,"") | I40: =IF(H40<>"",IF(H40<$K$6,($C$5/$K$6)*H40,IF(H40=$K$6,($C$5+0),IF(H40>$K$6,($C$5+0),""))),"") | J40: =IF(H40<>"",IF(I40<$K$10,E$7*30%,IF(AND(I40>$K$8,I40<$K$12),$E$7*60%,IF(I40>=$K$12,$E$7*100%,""))),"")
H41: =IF(Proposal!$C$19>24,'OIT SaaS'!H40+1,"") | I41: =IF(H41<>"",IF(H41<$K$6,($C$5/$K$6)*H41,IF(H41=$K$6,($C$5+0),IF(H41>$K$6,($C$5+0),""))),"") | J41: =IF(H41<>"",IF(I41<$K$10,E$7*30%,IF(AND(I41>$K$8,I41<$K$12),$E$7*60%,IF(I41>=$K$12,$E$7*100%,""))),"")
...

Sheet Modules
A1: 2 | C1: =HLOOKUP('General Information'!$C$6,'IDIOMA (hide)'!$A$1:$D$5016,A1,0) -> LTEP - Levantamento Técnico de Estimativa de Projeto TASY EMR Código do documento: 0060 - Rev 024
A3: 41 | B3: =HLOOKUP('General Information'!$C$6,'IDIOMA (hide)'!$A$1:$D$5016,A3,0) -> Informações Módulos de Interesse | C3: =HLOOKUP($F$4,'IDIOMA (hide)'!$A$1:$D$5016,B3,0) -> #N/A | D3: =HLOOKUP($F$4,'IDIOMA (hide)'!$A$1:$D$5016,C3,0) -> #N/A | E3: =HLOOKUP($F$4,'IDIOMA (hide)'!$A$1:$D$5016,D3,0) -> #N/A | F3: =HLOOKUP($F$4,'IDIOMA (hide)'!$A$1:$D$5016,E3,0) -> #N/A | G3: =HLOOKUP($F$4,'IDIOMA (hide)'!$A$1:$D$5016,F3,0) -> #N/A
B4: 42 | C4: 43 | D4: 44
B5: =HLOOKUP('General Information'!$C$6,'IDIOMA (hide)'!$A$1:$D$5016,B4,0) -> ID Módulo | C5: =HLOOKUP('General Information'!$C$6,'IDIOMA (hide)'!$A$1:$D$5016,C4,0) -> Módulo | D5: =HLOOKUP('General Information'!$C$6,'IDIOMA (hide)'!$A$1:$D$5016,D4,0) -> Interesse? | E5: Ocultar | F5: Área | K5: Módulo | L5: Interesse? | M5: Área
B6: 3 | C6: =IF('General Information'!$C$6="Português",VLOOKUP(Modules!B6,'ESTRUTURA_MODULO(hide)'!A:D,2,0),IF('General Information'!$C$6="English",VLOOKUP(Modules!B6,'ESTRUTURA_MODULO(hide)'!A:D,3,0),IF('General Information'!$C$6="Español",VLOOKUP(Modules!B6,'ESTRUTURA_MODULO(hide)'!A:D,4,0)))) -> Cadastros e Funções Gerais | D6: Yes | E6: =IF(OR(D6='Listas (Hide)'!$B$17,D6='Listas (Hide)'!$C$17,D6='Listas (Hide)'!$D$17)=TRUE,1,IF(OR(D6='Listas (Hide)'!$B$18,D6='Listas (Hide)'!$C$18,D6='Listas (Hide)'!$D$18)=TRUE,2,"")) -> 1 | F6: =HLOOKUP('General Information'!$C$6,'IDIOMA (hide)'!$A$1:$D$5016,G8,0) -> Core do sistema | K6: Cadastros e Funções Gerais | L6: =D6 -> Yes | M6: Core do sistema
B7: 36 | C7: =IF('General Information'!$C$6="Português",VLOOKUP(Modules!B7,'ESTRUTURA_MODULO(hide)'!A:D,2,0),IF('General Information'!$C$6="English",VLOOKUP(Modules!B7,'ESTRUTURA_MODULO(hide)'!A:D,3,0),IF('General Information'!$C$6="Español",VLOOKUP(Modules!B7,'ESTRUTURA_MODULO(hide)'!A:D,4,0)))) -> Gerenciador do Sistema | D7: Yes | E7: =IF(OR(D7='Listas (Hide)'!$B$17,D7='Listas (Hide)'!$C$17,D7='Listas (Hide)'!$D$17)=TRUE,1,IF(OR(D7='Listas (Hide)'!$B$18,D7='Listas (Hide)'!$C$18,D7='Listas (Hide)'!$D$18)=TRUE,2,"")) -> 1 | K7: Gerenciador do Sistema | L7: =D7 -> Yes | M7: Core do sistema
B8: 631 | C8: =IF('General Information'!$C$6="Português",VLOOKUP(Modules!B8,'ESTRUTURA_MODULO(hide)'!A:D,2,0),IF('General Information'!$C$6="English",VLOOKUP(Modules!B8,'ESTRUTURA_MODULO(hide)'!A:D,3,0),IF('General Information'!$C$6="Español",VLOOKUP(Modules!B8,'ESTRUTURA_MODULO(hide)'!A:D,4,0)))) -> Relatórios | D8: Yes | E8: =IF(OR(D8='Listas (Hide)'!$B$17,D8='Listas (Hide)'!$C$17,D8='Listas (Hide)'!$D$17)=TRUE,1,IF(OR(D8='Listas (Hide)'!$B$18,D8='Listas (Hide)'!$C$18,D8='Listas (Hide)'!$D$18)=TRUE,2,"")) -> 1 | G8: 203 | K8: Relatórios | L8: =D8 -> Yes | M8: Core do sistema
B9: 5 | C9: =IF('General Information'!$C$6="Português",VLOOKUP(Modules!B9,'ESTRUTURA_MODULO(hide)'!A:D,2,0),IF('General Information'!$C$6="English",VLOOKUP(Modules!B9,'ESTRUTURA_MODULO(hide)'!A:D,3,0),IF('General Information'!$C$6="Español",VLOOKUP(Modules!B9,'ESTRUTURA_MODULO(hide)'!A:D,4,0)))) -> Recepção e Internação | D9: =IF('General Information'!$C$18="OPS (Operadora de Saúde)","No","Yes") -> Yes | E9: =IF(OR(D9='Listas (Hide)'!$B$17,D9='Listas (Hide)'!$C$17,D9='Listas (Hide)'!$D$17)=TRUE,1,IF(OR(D9='Listas (Hide)'!$B$18,D9='Listas (Hide)'!$C$18,D9='Listas (Hide)'!$D$18)=TRUE,2,"")) -> 1 | K9: Recepção e Internação | L9: =D9 -> Yes | M9: Core do sistema
B10: 16 | C10: =IF('General Information'!$C$6="Português",VLOOKUP(Modules!B10,'ESTRUTURA_MODULO(hide)'!A:D,2,0),IF('General Information'!$C$6="English",VLOOKUP(Modules!B10,'ESTRUTURA_MODULO(hide)'!A:D,3,0),IF('General Information'!$C$6="Español",VLOOKUP(Modules!B10,'ESTRUTURA_MODULO(hide)'!A:D,4,0)))) -> Administração de Contratos (Preços) | D10: =IF('General Information'!$C$18="OPS (Operadora de Saúde)","No","Yes") -> Yes | E10: =IF(OR(D10='Listas (Hide)'!$B$17,D10='Listas (Hide)'!$C$17,D10='Listas (Hide)'!$D$17)=TRUE,1,IF(OR(D10='Listas (Hide)'!$B$18,D10='Listas (Hide)'!$C$18,D10='Listas (Hide)'!$D$18)=TRUE,2,"")) -> 1 | K10: Administração de Contratos (Preços) | L10: =D10 -> Yes | M10: Core do sistema
B11: 6 | C11: =IF('General Information'!$C$6="Português",VLOOKUP(Modules!B11,'ESTRUTURA_MODULO(hide)'!A:D,2,0),IF('General Information'!$C$6="English",VLOOKUP(Modules!B11,'ESTRUTURA_MODULO(hide)'!A:D,3,0),IF('General Information'!$C$6="Español",VLOOKUP(Modules!B11,'ESTRUTURA_MODULO(hide)'!A:D,4,0)))) -> Faturamento (Convênios e Particular) | D11: =IF('General Information'!$C$18="OPS (Operadora de Saúde)","No","Yes") -> Yes | E11: =IF(OR(D11='Listas (Hide)'!$B$17,D11='Listas (Hide)'!$C$17,D11='Listas (Hide)'!$D$17)=TRUE,1,IF(OR(D11='Listas (Hide)'!$B$18,D11='Listas (Hide)'!$C$18,D11='Listas (Hide)'!$D$18)=TRUE,2,"")) -> 1 | K11: Faturamento (Convênios e Particular) | L11: =D11 -> Yes | M11: Core do sistema
B12: 99 | C12: =IF('General Information'!$C$6="Português",VLOOKUP(Modules!B12,'ESTRUTURA_MODULO(hide)'!A:D,2,0),IF('General Information'!$C$6="English",VLOOKUP(Modules!B12,'ESTRUTURA_MODULO(hide)'!A:D,3,0),IF('General Information'!$C$6="Español",VLOOKUP(Modules!B12,'ESTRUTURA_MODULO(hide)'!A:D,4,0)))) -> Almoxarifado | D12: Yes | E12: =IF(OR(D12='Listas (Hide)'!$B$17,D12='Listas (Hide)'!$C$17,D12='Listas (Hide)'!$D$17)=TRUE,1,IF(OR(D12='Listas (Hide)'!$B$18,D12='Listas (Hide)'!$C$18,D12='Listas (Hide)'!$D$18)=TRUE,2,"")) -> 1 | K12: Almoxarifado | L12: =D12 -> Yes | M12: Core do sistema
B13: 4 | C13: =IF('General Information'!$C$6="Português",VLOOKUP(Modules!B13,'ESTRUTURA_MODULO(hide)'!A:D,2,0),IF('General Information'!$C$6="English",VLOOKUP(Modules!B13,'ESTRUTURA_MODULO(hide)'!A:D,3,0),IF('General Information'!$C$6="Español",VLOOKUP(Modules!B13,'ESTRUTURA_MODULO(hide)'!A:D,4,0)))) -> Estoque | D13: Yes | E13: =IF(OR(D13='Listas (Hide)'!$B$17,D13='Listas (Hide)'!$C$17,D13='Listas (Hide)'!$D$17)=TRUE,1,IF(OR(D13='Listas (Hide)'!$B$18,D13='Listas (Hide)'!$C$18,D13='Listas (Hide)'!$D$18)=TRUE,2,"")) -> 1 | K13: Estoque | L13: =D13 -> Yes | M13: Core do sistema
B14: 87 | C14: =IF('General Information'!$C$6="Português",VLOOKUP(Modules!B14,'ESTRUTURA_MODULO(hide)'!A:D,2,0),IF('General Information'!$C$6="English",VLOOKUP(Modules!B14,'ESTRUTURA_MODULO(hide)'!A:D,3,0),IF('General Information'!$C$6="Español",VLOOKUP(Modules!B14,'ESTRUTURA_MODULO(hide)'!A:D,4,0)))) -> Agenda | D14: No | E14: =IF(OR(D14='Listas (Hide)'!$B$17,D14='Listas (Hide)'!$C$17,D14='Listas (Hide)'!$D$17)=TRUE,1,IF(OR(D14='Listas (Hide)'!$B$18,D14='Listas (Hide)'!$C$18,D14='Listas (Hide)'!$D$18)=TRUE,2,"")) -> 2 | F14: =HLOOKUP('General Information'!$C$6,'IDIOMA (hide)'!$A$1:$D$5016,G14,0) -> Atendimento | G14: 204 | K14: Agenda | L14: =D14 -> No | M14: Atendimento
B15: 20 | C15: =IF('General Information'!$C$6="Português",VLOOKUP(Modules!B15,'ESTRUTURA_MODULO(hide)'!A:D,2,0),IF('General Information'!$C$6="English",VLOOKUP(Modules!B15,'ESTRUTURA_MODULO(hide)'!A:D,3,0),IF('General Information'!$C$6="Español",VLOOKUP(Modules!B15,'ESTRUTURA_MODULO(hide)'!A:D,4,0)))) -> SAC | D15: No | E15: =IF(OR(D15='Listas (Hide)'!$B$17,D15='Listas (Hide)'!$C$17,D15='Listas (Hide)'!$D$17)=TRUE,1,IF(OR(D15='Listas (Hide)'!$B$18,D15='Listas (Hide)'!$C$18,D15='Listas (Hide)'!$D$18)=TRUE,2,"")) -> 2 | K15: SAC | L15: =D15 -> No | M15: Atendimento
B16: 455 | C16: =IF('General Information'!$C$6="Português",VLOOKUP(Modules!B16,'ESTRUTURA_MODULO(hide)'!A:D,2,0),IF('General Information'!$C$6="English",VLOOKUP(Modules!B16,'ESTRUTURA_MODULO(hide)'!A:D,3,0),IF('General Information'!$C$6="Español",VLOOKUP(Modules!B16,'ESTRUTURA_MODULO(hide)'!A:D,4,0)))) -> Visitas | D16: No | E16: =IF(OR(D16='Listas (Hide)'!$B$17,D16='Listas (Hide)'!$C$17,D16='Listas (Hide)'!$D$17)=TRUE,1,IF(OR(D16='Listas (Hide)'!$B$18,D16='Listas (Hide)'!$C$18,D16='Listas (Hide)'!$D$18)=TRUE,2,"")) -> 2 | K16: Visitas | L16: =D16 -> No | M16: Atendimento
B17: 88 | C17: =IF('General Information'!$C$6="Português",VLOOKUP(Modules!B17,'ESTRUTURA_MODULO(hide)'!A:D,2,0),IF('General Information'!$C$6="English",VLOOKUP(Modules!B17,'ESTRUTURA_MODULO(hide)'!A:D,3,0),IF('General Information'!$C$6="Español",VLOOKUP(Modules!B17,'ESTRUTURA_MODULO(hide)'!A:D,4,0)))) -> Prontuário Eletrônico | D17: No | E17: =IF(OR(D17='Listas (Hide)'!$B$17,D17='Listas (Hide)'!$C$17,D17='Listas (Hide)'!$D$17)=TRUE,1,IF(OR(D17='Listas (Hide)'!$B$18,D17='Listas (Hide)'!$C$18,D17='Listas (Hide)'!$D$18)=TRUE,2,"")) -> 2 | F17: =HLOOKUP('General Information'!$C$6,'IDIOMA (hide)'!$A$1:$D$5016,G17,0) -> Assistencial | G17: 205 | K17: Prontuário Eletrônico | L17: =D17 -> No | M17: Assistencial
B18: 10 | C18: =IF('General Information'!$C$6="Português",VLOOKUP(Modules!B18,'ESTRUTURA_MODULO(hide)'!A:D,2,0),IF('General Information'!$C$6="English",VLOOKUP(Modules!B18,'ESTRUTURA_MODULO(hide)'!A:D,3,0),IF('General Information'!$C$6="Español",VLOOKUP(Modules!B18,'ESTRUTURA_MODULO(hide)'!A:D,4,0)))) -> Prescrição Eletrônica | D18: No | E18: =IF(OR(D18='Listas (Hide)'!$B$17,D18='Listas (Hide)'!$C$17,D18='Listas (Hide)'!$D$17)=TRUE,1,IF(OR(D18='Listas (Hide)'!$B$18,D18='Listas (Hide)'!$C$18,D18='Listas (Hide)'!$D$18)=TRUE,2,"")) -> 2 | K18: Prescrição Eletrônica | L18: =D18 -> No | M18: Assistencial
B19: 870 | C19: =IF('General Information'!$C$6="Português",VLOOKUP(Modules!B19,'ESTRUTURA_MODULO(hide)'!A:D,2,0),IF('General Information'!$C$6="English",VLOOKUP(Modules!B19,'ESTRUTURA_MODULO(hide)'!A:D,3,0),IF('General Information'!$C$6="Español",VLOOKUP(Modules!B19,'ESTRUTURA_MODULO(hide)'!A:D,4,0)))) -> Suporte a Decisão Clínica | D19: No | E19: =IF(OR(D19='Listas (Hide)'!$B$17,D19='Listas (Hide)'!$C$17,D19='Listas (Hide)'!$D$17)=TRUE,1,IF(OR(D19='Listas (Hide)'!$B$18,D19='Listas (Hide)'!$C$18,D19='Listas (Hide)'!$D$18)=TRUE,2,"")) -> 2 | K19: Suporte a Decisão Clínica | L19: =D19 -> No | M19: Assistencial
B20: 38 | C20: =IF('General Information'!$C$6="Português",VLOOKUP(Modules!B20,'ESTRUTURA_MODULO(hide)'!A:D,2,0),IF('General Information'!$C$6="English",VLOOKUP(Modules!B20,'ESTRUTURA_MODULO(hide)'!A:D,3,0),IF('General Information'!$C$6="Español",VLOOKUP(Modules!B20,'ESTRUTURA_MODULO(hide)'!A:D,4,0)))) -> Enfermagem | D20: No | E20: =IF(OR(D20='Listas (Hide)'!$B$17,D20='Listas (Hide)'!$C$17,D20='Listas (Hide)'!$D$17)=TRUE,1,IF(OR(D20='Listas (Hide)'!$B$18,D20='Listas (Hide)'!$C$18,D20='Listas (Hide)'!$D$18)=TRUE,2,"")) -> 2 | K20: Enfermagem | L20: =D20 -> No | M20: Assistencial
B21: 89 | C21: =IF('General Information'!$C$6="Português",VLOOKUP(Modules!B21,'ESTRUTURA_MODULO(hide)'!A:D,2,0),IF('General Information'!$C$6="English",VLOOKUP(Modules!B21,'ESTRUTURA_MODULO(hide)'!A:D,3,0),IF('General Information'!$C$6="Español",VLOOKUP(Modules!B21,'ESTRUTURA_MODULO(hide)'!A:D,4,0)))) -> Pronto Atendimento | D21: No | E21: =IF(OR(D21='Listas (Hide)'!$B$17,D21='Listas (Hide)'!$C$17,D21='Listas (Hide)'!$D$17)=TRUE,1,IF(OR(D21='Listas (Hide)'!$B$18,D21='Listas (Hide)'!$C$18,D21='Listas (Hide)'!$D$18)=TRUE,2,"")) -> 2 | K21: Pronto Atendimento | L21: =D21 -> No | M21: Assistencial
